Workbook

Sheet README
A1: Audit analytics toolkit: Benford, duplicate payments, round sums and journal entry tests
A2: Sample / demonstration data only. No real company, vendor, employee or transaction.
A4: PURPOSE
A5: Run standard data analytics over a year of payments and journal entries, score each item, and produce a ranked list for targeted follow up. Anomalies were seeded into the sample data so detection can be tested against an answer key.
A7: SHEETS
A8: Parameters: thresholds, weights, authorised users (inputs, blue). Change a value and every flag recalculates.
A9: Vendors, Employees: master data used by the bank account match.
A10: Payments: one row per payment. Blue = input, black = formula. Flags and score are columns to the right.
A11: Benford: first digit test over all payments (counts, z statistics, MAD, chi square) with a chart.
A12: Vendor_Benford: the same test per vendor, plus the employee bank account match.
A13: COA, JE_Lines: chart of accounts and journal entry lines (inputs).
A14: JE_Entries: one row per journal entry number (number in brown from the engine, everything else formulas), with tests and score.
... A34: Blue font = input. Brown font = engine output pasted as values. Black = formula.

Sheet Parameters
A1: Parameters
A2: Sample / demonstration data only. No real company, vendor, employee or transaction.
A3: Inputs in blue. Weights drive the risk scores.
A4: Parameter | B4: Value | C4: Note
A5: Fiscal year start | B5: 45658 | C5: Population period
A6: Fiscal year end | B6: 46022 | C6: Population period
A7: Payment approval limit (USD) | B7: 5000 | C7: Payments at or above need the senior approver
A8: Senior approver code | B8: FIN_DIR | C8: Approver required at or above the limit
A9: Below limit band | B9: 0.05 | C9: Flag payments within this share below the limit
A10: Round sum modulus (USD) | B10: 1000 | C10: Amount is a multiple of this
A11: Round sum minimum (USD) | B11: 1000 | C11: Ignore smaller round amounts
A12: Near duplicate window (days) | B12: 30 | C12: Same vendor and amount within this many days
A13: Benford minimum payments per vendor | B13: 30 | C13: Vendor test is unreliable below this count
A14: Benford MAD threshold | B14: 0.015 | C14: First digit MAD above this is nonconformity (Nigrini)
A15: Benford z critical value | B15: 1.96 | C15: 5 percent two sided
A16: Chi square critical value (8 df, 5 percent) | B16: 15.507 | C16: Fixed statistical constant
A17: JE posting lag limit (days) | B17: 15 | C17: Posting date less document date
A18: Period end window (days) | B18: 3 | C18: Last days of the fiscal year
A19: JE approval limit (USD) | B19: 50000 | C19: Manual entries need extra approval at or above
A20: JE below limit band | B20: 0.05 | C20: Flag manual entries within this share below the limit
... A25: High risk cutoff, journal entries (score) | B25: 5 | C25: Score at or above is High
A27: Payment risk weights
A28: Duplicate payment (same vendor, invoice, amount) | B28: 5
A29: Near duplicate (same vendor and amount, different invoice) | B29: 3
A30: Round sum | B30: 2
A31: Just below approval limit | B31: 2
A32: Same day split above limit | B32: 3
A33: Approved below required authority | B33: 4
A34: Vendor bank account matches an employee | B34: 5
A35: Vendor fails Benford test | B35: 2
A37: Journal entry risk weights
A38: Unbalanced entry | B38: 5
A39: Posted on weekend | B39: 2
A40: Posted late versus document date | B40: 2
A41: Posted in last days of year | B41: 1
A42: Posted by user not authorised | B42: 3
A43: Manual entry to revenue | B43: 3
A44: Round total | B44: 2
A45: No description | B45: 2
A46: Manual entry just below approval limit | B46: 3
...

Sheet Vendors
A1: Vendor master
A2: Sample / demonstration data only. No real company, vendor, employee or transaction.
A3: Synthetic. V038 bank account equals an employee bank account (seeded).
A4: Vendor ID | B4: Vendor name | C4: Bank account
A5: V001 | B5: Sample Supplier 001 | C5: ACC00104784
A6: V002 | B6: Sample Supplier 002 | C6: ACC00209513
A7: V003 | B7: Sample Supplier 003 | C7: ACC00314242
A8: V004 | B8: Sample Supplier 004 | C8: ACC00418971
A9: V005 | B9: Sample Supplier 005 | C9: ACC00523700
A10: V006 | B10: Sample Supplier 006 | C10: ACC00628429
A11: V007 | B11: Sample Supplier 007 | C11: ACC00733158
A12: V008 | B12: Sample Supplier 008 | C12: ACC00837887
A13: V009 | B13: Sample Supplier 009 | C13: ACC00942616
A14: V010 | B14: Sample Supplier 010 | C14: ACC01047345
A15: V011 | B15: Sample Supplier 011 | C15: ACC01152074
... A49: V045 | B49: Sample Supplier 045 | C49: ACC04712860

Sheet Employees
A1: Employee master
A2: Sample / demonstration data only. No real company, vendor, employee or transaction.
A3: Synthetic.
A4: Employee ID | B4: Bank account
A5: E001 | B5: ACC15485863
A6: E002 | B6: ACC30971726
A7: E003 | B7: ACC46457589
A8: E004 | B8: ACC61943452
A9: E005 | B9: ACC77429315
A10: E006 | B10: ACC92915178
A11: E007 | B11: ACC08401041
A12: E008 | B12: ACC23886904
A13: E009 | B13: ACC39372767
A14: E010 | B14: ACC54858630
A15: E011 | B15: ACC70344493
... A29: E025 | B29: ACC87146575

Sheet Payments
A1: Payments
A2: Sample / demonstration data only. No real company, vendor, employee or transaction.
A3: Columns A to F are inputs. Columns G onward are formulas.
A4: Payment ID | B4: Payment date | C4: Vendor | D4: Invoice no | E4: Amount (USD) | F4: Approver | G4: First digit | H4: Normalised invoice | I4: Duplicate | J4: Near duplicate | K4: Round sum | L4: Below limit | M4: Same day split | N4: Authority breach | O4: Employee bank match | P4: Vendor Benford flag | Q4: Risk score | R4: Priority
A5: P0001 | B5: 45658 | C5: V001 | D5: RENT2501 | E5: 85000 | F5: FIN_DIR | G5: =VALUE(LEFT(TEXT(E5,"0.00"),1)) -> 8 | H5: =UPPER(SUBSTITUTE(SUBSTITUTE(SUBSTITUTE(D5," ",""),"/",""),".","")) -> RENT2501 | I5: =IF(COUNTIFS($C$5:C5,C5,$H$5:H5,H5,$E$5:E5,E5)>1,1,0) -> 0 | J5: =IF(AND(I5=0,COUNTIFS($C$5:$C$634,C5,$E$5:$E$634,E5,$B$5:$B$634,">="&(B5-Parameters!$B$12),$B$5:$B$634,"<="&(B5+Parameters!$B$12),$H$5:$H$634,"<>"&H5)>0),1,0) -> 0 | K5: =IF(AND(E5>=Parameters!$B$11,ROUND(MOD(ROUND(E5,2),Parameters!$B$10),2)=0),1,0) -> 1 | L5: =IF(AND(E5<Parameters!$B$7,E5>=Parameters!$B$7*(1-Parameters!$B$9)),1,0) -> 0 | M5: =IF(AND(E5<Parameters!$B$7,COUNTIFS($C$5:$C$634,C5,$B$5:$B$634,B5)>1,SUMIFS($E$5:$E$634,$C$5:$C$634,C5,$B$5:$B$634,B5)>=Parameters!$B$7),1,0) -> 0 | N5: =IF(AND(E5>=Parameters!$B$7,F5<>Parameters!$B$8),1,0) -> 0 | O5: =INDEX(Vendor_Benford!$N$6:$N$50,MATCH(C5,Vendor_Benford!$A$6:$A$50,0)) -> 0 | P5: =INDEX(Vendor_Benford!$M$6:$M$50,MATCH(C5,Vendor_Benford!$A$6:$A$50,0)) -> 0 | Q5: =I5*Parameters!$B$28+J5*Parameters!$B$29+K5*Parameters!$B$30+L5*Parameters!$B$31+M5*Parameters!$B$32+N5*Parameters!$B$33+O5*Parameters!$B$34+P5*Parameters!$B$35 -> 2 | R5: =IF(Q5>=Parameters!$B$24,"High","")
A6: P0002 | B6: 45658 | C6: V010 | D6: INV10007 | E6: 45000 | F6: FIN_DIR | G6: =VALUE(LEFT(TEXT(E6,"0.00"),1)) -> 4 | H6: =UPPER(SUBSTITUTE(SUBSTITUTE(SUBSTITUTE(D6," ",""),"/",""),".","")) -> INV10007 | I6: =IF(COUNTIFS($C$5:C6,C6,$H$5:H6,H6,$E$5:E6,E6)>1,1,0) -> 0 | J6: =IF(AND(I6=0,COUNTIFS($C$5:$C$634,C6,$E$5:$E$634,E6,$B$5:$B$634,">="&(B6-Parameters!$B$12),$B$5:$B$634,"<="&(B6+Parameters!$B$12),$H$5:$H$634,"<>"&H6)>0),1,0) -> 0 | K6: =IF(AND(E6>=Parameters!$B$11,ROUND(MOD(ROUND(E6,2),Parameters!$B$10),2)=0),1,0) -> 1 | L6: =IF(AND(E6<Parameters!$B$7,E6>=Parameters!$B$7*(1-Parameters!$B$9)),1,0) -> 0 | M6: =IF(AND(E6<Parameters!$B$7,COUNTIFS($C$5:$C$634,C6,$B$5:$B$634,B6)>1,SUMIFS($E$5:$E$634,$C$5:$C$634,C6,$B$5:$B$634,B6)>=Parameters!$B$7),1,0) -> 0 | N6: =IF(AND(E6>=Parameters!$B$7,F6<>Parameters!$B$8),1,0) -> 0 | O6: =INDEX(Vendor_Benford!$N$6:$N$50,MATCH(C6,Vendor_Benford!$A$6:$A$50,0)) -> 0 | P6: =INDEX(Vendor_Benford!$M$6:$M$50,MATCH(C6,Vendor_Benford!$A$6:$A$50,0)) -> 0 | Q6: =I6*Parameters!$B$28+J6*Parameters!$B$29+K6*Parameters!$B$30+L6*Parameters!$B$31+M6*Parameters!$B$32+N6*Parameters!$B$33+O6*Parameters!$B$34+P6*Parameters!$B$35 -> 2 | R6: =IF(Q6>=Parameters!$B$24,"High","")
A7: P0003 | B7: 45658 | C7: V030 | D7: INV30011 | E7: 684.73 | F7: FIN_DIR | G7: =VALUE(LEFT(TEXT(E7,"0.00"),1)) -> 6 | H7: =UPPER(SUBSTITUTE(SUBSTITUTE(SUBSTITUTE(D7," ",""),"/",""),".","")) -> INV30011 | I7: =IF(COUNTIFS($C$5:C7,C7,$H$5:H7,H7,$E$5:E7,E7)>1,1,0) -> 0 | J7: =IF(AND(I7=0,COUNTIFS($C$5:$C$634,C7,$E$5:$E$634,E7,$B$5:$B$634,">="&(B7-Parameters!$B$12),$B$5:$B$634,"<="&(B7+Parameters!$B$12),$H$5:$H$634,"<>"&H7)>0),1,0) -> 0 | K7: =IF(AND(E7>=Parameters!$B$11,ROUND(MOD(ROUND(E7,2),Parameters!$B$10),2)=0),1,0) -> 0 | L7: =IF(AND(E7<Parameters!$B$7,E7>=Parameters!$B$7*(1-Parameters!$B$9)),1,0) -> 0 | M7: =IF(AND(E7<Parameters!$B$7,COUNTIFS($C$5:$C$634,C7,$B$5:$B$634,B7)>1,SUMIFS($E$5:$E$634,$C$5:$C$634,C7,$B$5:$B$634,B7)>=Parameters!$B$7),1,0) -> 0 | N7: =IF(AND(E7>=Parameters!$B$7,F7<>Parameters!$B$8),1,0) -> 0 | O7: =INDEX(Vendor_Benford!$N$6:$N$50,MATCH(C7,Vendor_Benford!$A$6:$A$50,0)) -> 0 | P7: =INDEX(Vendor_Benford!$M$6:$M$50,MATCH(C7,Vendor_Benford!$A$6:$A$50,0)) -> 0 | Q7: =I7*Parameters!$B$28+J7*Parameters!$B$29+K7*Parameters!$B$30+L7*Parameters!$B$31+M7*Parameters!$B$32+N7*Parameters!$B$33+O7*Parameters!$B$34+P7*Parameters!$B$35 -> 0 | R7: =IF(Q7>=Parameters!$B$24,"High","")
A8: P0004 | B8: 45658 | C8: V039 | D8: INV39011 | E8: 14935.84 | F8: FIN_DIR | G8: =VALUE(LEFT(TEXT(E8,"0.00"),1)) -> 1 | H8: =UPPER(SUBSTITUTE(SUBSTITUTE(SUBSTITUTE(D8," ",""),"/",""),".","")) -> INV39011 | I8: =IF(COUNTIFS($C$5:C8,C8,$H$5:H8,H8,$E$5:E8,E8)>1,1,0) -> 0 | J8: =IF(AND(I8=0,COUNTIFS($C$5:$C$634,C8,$E$5:$E$634,E8,$B$5:$B$634,">="&(B8-Parameters!$B$12),$B$5:$B$634,"<="&(B8+Parameters!$B$12),$H$5:$H$634,"<>"&H8)>0),1,0) -> 0 | K8: =IF(AND(E8>=Parameters!$B$11,ROUND(MOD(ROUND(E8,2),Parameters!$B$10),2)=0),1,0) -> 0 | L8: =IF(AND(E8<Parameters!$B$7,E8>=Parameters!$B$7*(1-Parameters!$B$9)),1,0) -> 0 | M8: =IF(AND(E8<Parameters!$B$7,COUNTIFS($C$5:$C$634,C8,$B$5:$B$634,B8)>1,SUMIFS($E$5:$E$634,$C$5:$C$634,C8,$B$5:$B$634,B8)>=Parameters!$B$7),1,0) -> 0 | N8: =IF(AND(E8>=Parameters!$B$7,F8<>Parameters!$B$8),1,0) -> 0 | O8: =INDEX(Vendor_Benford!$N$6:$N$50,MATCH(C8,Vendor_Benford!$A$6:$A$50,0)) -> 0 | P8: =INDEX(Vendor_Benford!$M$6:$M$50,MATCH(C8,Vendor_Benford!$A$6:$A$50,0)) -> 0 | Q8: =I8*Parameters!$B$28+J8*Parameters!$B$29+K8*Parameters!$B$30+L8*Parameters!$B$31+M8*Parameters!$B$32+N8*Parameters!$B$33+O8*Parameters!$B$34+P8*Parameters!$B$35 -> 0 | R8: =IF(Q8>=Parameters!$B$24,"High","")
A9: P0005 | B9: 45658 | C9: V042 | D9: INV42010 | E9: 5020.85 | F9: FIN_DIR | G9: =VALUE(LEFT(TEXT(E9,"0.00"),1)) -> 5 | H9: =UPPER(SUBSTITUTE(SUBSTITUTE(SUBSTITUTE(D9," ",""),"/",""),".","")) -> INV42010 | I9: =IF(COUNTIFS($C$5:C9,C9,$H$5:H9,H9,$E$5:E9,E9)>1,1,0) -> 0 | J9: =IF(AND(I9=0,COUNTIFS($C$5:$C$634,C9,$E$5:$E$634,E9,$B$5:$B$634,">="&(B9-Parameters!$B$12),$B$5:$B$634,"<="&(B9+Parameters!$B$12),$H$5:$H$634,"<>"&H9)>0),1,0) -> 0 | K9: =IF(AND(E9>=Parameters!$B$11,ROUND(MOD(ROUND(E9,2),Parameters!$B$10),2)=0),1,0) -> 0 | L9: =IF(AND(E9<Parameters!$B$7,E9>=Parameters!$B$7*(1-Parameters!$B$9)),1,0) -> 0 | M9: =IF(AND(E9<Parameters!$B$7,COUNTIFS($C$5:$C$634,C9,$B$5:$B$634,B9)>1,SUMIFS($E$5:$E$634,$C$5:$C$634,C9,$B$5:$B$634,B9)>=Parameters!$B$7),1,0) -> 0 | N9: =IF(AND(E9>=Parameters!$B$7,F9<>Parameters!$B$8),1,0) -> 0 | O9: =INDEX(Vendor_Benford!$N$6:$N$50,MATCH(C9,Vendor_Benford!$A$6:$A$50,0)) -> 0 | P9: =INDEX(Vendor_Benford!$M$6:$M$50,MATCH(C9,Vendor_Benford!$A$6:$A$50,0)) -> 0 | Q9: =I9*Parameters!$B$28+J9*Parameters!$B$29+K9*Parameters!$B$30+L9*Parameters!$B$31+M9*Parameters!$B$32+N9*Parameters!$B$33+O9*Parameters!$B$34+P9*Parameters!$B$35 -> 0 | R9: =IF(Q9>=Parameters!$B$24,"High","")
A10: P0006 | B10: 45659 | C10: V044 | D10: INV44006 | E10: 20651.24 | F10: FIN_DIR | G10: =VALUE(LEFT(TEXT(E10,"0.00"),1)) -> 2 | H10: =UPPER(SUBSTITUTE(SUBSTITUTE(SUBSTITUTE(D10," ",""),"/",""),".","")) -> INV44006 | I10: =IF(COUNTIFS($C$5:C10,C10,$H$5:H10,H10,$E$5:E10,E10)>1,1,0) -> 0 | J10: =IF(AND(I10=0,COUNTIFS($C$5:$C$634,C10,$E$5:$E$634,E10,$B$5:$B$634,">="&(B10-Parameters!$B$12),$B$5:$B$634,"<="&(B10+Parameters!$B$12),$H$5:$H$634,"<>"&H10)>0),1,0) -> 0 | K10: =IF(AND(E10>=Parameters!$B$11,ROUND(MOD(ROUND(E10,2),Parameters!$B$10),2)=0),1,0) -> 0 | L10: =IF(AND(E10<Parameters!$B$7,E10>=Parameters!$B$7*(1-Parameters!$B$9)),1,0) -> 0 | M10: =IF(AND(E10<Parameters!$B$7,COUNTIFS($C$5:$C$634,C10,$B$5:$B$634,B10)>1,SUMIFS($E$5:$E$634,$C$5:$C$634,C10,$B$5:$B$634,B10)>=Parameters!$B$7),1,0) -> 0 | N10: =IF(AND(E10>=Parameters!$B$7,F10<>Parameters!$B$8),1,0) -> 0 | O10: =INDEX(Vendor_Benford!$N$6:$N$50,MATCH(C10,Vendor_Benford!$A$6:$A$50,0)) -> 0 | P10: =INDEX(Vendor_Benford!$M$6:$M$50,MATCH(C10,Vendor_Benford!$A$6:$A$50,0)) -> 0 | Q10: =I10*Parameters!$B$28+J10*Parameters!$B$29+K10*Parameters!$B$30+L10*Parameters!$B$31+M10*Parameters!$B$32+N10*Parameters!$B$33+O10*Parameters!$B$34+P10*Parameters!$B$35 -> 0 | R10: =IF(Q10>=Parameters!$B$24,"High","")
A11: P0007 | B11: 45659 | C11: V045 | D11: INV45004 | E11: 9042.65 | F11: FIN_DIR | G11: =VALUE(LEFT(TEXT(E11,"0.00"),1)) -> 9 | H11: =UPPER(SUBSTITUTE(SUBSTITUTE(SUBSTITUTE(D11," ",""),"/",""),".","")) -> INV45004 | I11: =IF(COUNTIFS($C$5:C11,C11,$H$5:H11,H11,$E$5:E11,E11)>1,1,0) -> 0 | J11: =IF(AND(I11=0,COUNTIFS($C$5:$C$634,C11,$E$5:$E$634,E11,$B$5:$B$634,">="&(B11-Parameters!$B$12),$B$5:$B$634,"<="&(B11+Parameters!$B$12),$H$5:$H$634,"<>"&H11)>0),1,0) -> 0 | K11: =IF(AND(E11>=Parameters!$B$11,ROUND(MOD(ROUND(E11,2),Parameters!$B$10),2)=0),1,0) -> 0 | L11: =IF(AND(E11<Parameters!$B$7,E11>=Parameters!$B$7*(1-Parameters!$B$9)),1,0) -> 0 | M11: =IF(AND(E11<Parameters!$B$7,COUNTIFS($C$5:$C$634,C11,$B$5:$B$634,B11)>1,SUMIFS($E$5:$E$634,$C$5:$C$634,C11,$B$5:$B$634,B11)>=Parameters!$B$7),1,0) -> 0 | N11: =IF(AND(E11>=Parameters!$B$7,F11<>Parameters!$B$8),1,0) -> 0 | O11: =INDEX(Vendor_Benford!$N$6:$N$50,MATCH(C11,Vendor_Benford!$A$6:$A$50,0)) -> 0 | P11: =INDEX(Vendor_Benford!$M$6:$M$50,MATCH(C11,Vendor_Benford!$A$6:$A$50,0)) -> 0 | Q11: =I11*Parameters!$B$28+J11*Parameters!$B$29+K11*Parameters!$B$30+L11*Parameters!$B$31+M11*Parameters!$B$32+N11*Parameters!$B$33+O11*Parameters!$B$34+P11*Parameters!$B$35 -> 0 | R11: =IF(Q11>=Parameters!$B$24,"High","")
A12: P0008 | B12: 45660 | C12: V012 | D12: INV12012 | E12: 6340.75 | F12: FIN_DIR | G12: =VALUE(LEFT(TEXT(E12,"0.00"),1)) -> 6 | H12: =UPPER(SUBSTITUTE(SUBSTITUTE(SUBSTITUTE(D12," ",""),"/",""),".","")) -> INV12012 | I12: =IF(COUNTIFS($C$5:C12,C12,$H$5:H12,H12,$E$5:E12,E12)>1,1,0) -> 0 | J12: =IF(AND(I12=0,COUNTIFS($C$5:$C$634,C12,$E$5:$E$634,E12,$B$5:$B$634,">="&(B12-Parameters!$B$12),$B$5:$B$634,"<="&(B12+Parameters!$B$12),$H$5:$H$634,"<>"&H12)>0),1,0) -> 0 | K12: =IF(AND(E12>=Parameters!$B$11,ROUND(MOD(ROUND(E12,2),Parameters!$B$10),2)=0),1,0) -> 0 | L12: =IF(AND(E12<Parameters!$B$7,E12>=Parameters!$B$7*(1-Parameters!$B$9)),1,0) -> 0 | M12: =IF(AND(E12<Parameters!$B$7,COUNTIFS($C$5:$C$634,C12,$B$5:$B$634,B12)>1,SUMIFS($E$5:$E$634,$C$5:$C$634,C12,$B$5:$B$634,B12)>=Parameters!$B$7),1,0) -> 0 | N12: =IF(AND(E12>=Parameters!$B$7,F12<>Parameters!$B$8),1,0) -> 0 | O12: =INDEX(Vendor_Benford!$N$6:$N$50,MATCH(C12,Vendor_Benford!$A$6:$A$50,0)) -> 0 | P12: =INDEX(Vendor_Benford!$M$6:$M$50,MATCH(C12,Vendor_Benford!$A$6:$A$50,0)) -> 0 | Q12: =I12*Parameters!$B$28+J12*Parameters!$B$29+K12*Parameters!$B$30+L12*Parameters!$B$31+M12*Parameters!$B$32+N12*Parameters!$B$33+O12*Parameters!$B$34+P12*Parameters!$B$35 -> 0 | R12: =IF(Q12>=Parameters!$B$24,"High","")
A13: P0009 | B13: 45660 | C13: V022 | D13: INV22005 | E13: 14791.69 | F13: FIN_DIR | G13: =VALUE(LEFT(TEXT(E13,"0.00"),1)) -> 1 | H13: =UPPER(SUBSTITUTE(SUBSTITUTE(SUBSTITUTE(D13," ",""),"/",""),".","")) -> INV22005 | I13: =IF(COUNTIFS($C$5:C13,C13,$H$5:H13,H13,$E$5:E13,E13)>1,1,0) -> 0 | J13: =IF(AND(I13=0,COUNTIFS($C$5:$C$634,C13,$E$5:$E$634,E13,$B$5:$B$634,">="&(B13-Parameters!$B$12),$B$5:$B$634,"<="&(B13+Parameters!$B$12),$H$5:$H$634,"<>"&H13)>0),1,0) -> 0 | K13: =IF(AND(E13>=Parameters!$B$11,ROUND(MOD(ROUND(E13,2),Parameters!$B$10),2)=0),1,0) -> 0 | L13: =IF(AND(E13<Parameters!$B$7,E13>=Parameters!$B$7*(1-Parameters!$B$9)),1,0) -> 0 | M13: =IF(AND(E13<Parameters!$B$7,COUNTIFS($C$5:$C$634,C13,$B$5:$B$634,B13)>1,SUMIFS($E$5:$E$634,$C$5:$C$634,C13,$B$5:$B$634,B13)>=Parameters!$B$7),1,0) -> 0 | N13: =IF(AND(E13>=Parameters!$B$7,F13<>Parameters!$B$8),1,0) -> 0 | O13: =INDEX(Vendor_Benford!$N$6:$N$50,MATCH(C13,Vendor_Benford!$A$6:$A$50,0)) -> 0 | P13: =INDEX(Vendor_Benford!$M$6:$M$50,MATCH(C13,Vendor_Benford!$A$6:$A$50,0)) -> 0 | Q13: =I13*Parameters!$B$28+J13*Parameters!$B$29+K13*Parameters!$B$30+L13*Parameters!$B$31+M13*Parameters!$B$32+N13*Parameters!$B$33+O13*Parameters!$B$34+P13*Parameters!$B$35 -> 0 | R13: =IF(Q13>=Parameters!$B$24,"High","")
A14: P0010 | B14: 45663 | C14: V003 | D14: INV3013 | E14: 65754.59 | F14: FIN_DIR | G14: =VALUE(LEFT(TEXT(E14,"0.00"),1)) -> 6 | H14: =UPPER(SUBSTITUTE(SUBSTITUTE(SUBSTITUTE(D14," ",""),"/",""),".","")) -> INV3013 | I14: =IF(COUNTIFS($C$5:C14,C14,$H$5:H14,H14,$E$5:E14,E14)>1,1,0) -> 0 | J14: =IF(AND(I14=0,COUNTIFS($C$5:$C$634,C14,$E$5:$E$634,E14,$B$5:$B$634,">="&(B14-Parameters!$B$12),$B$5:$B$634,"<="&(B14+Parameters!$B$12),$H$5:$H$634,"<>"&H14)>0),1,0) -> 0 | K14: =IF(AND(E14>=Parameters!$B$11,ROUND(MOD(ROUND(E14,2),Parameters!$B$10),2)=0),1,0) -> 0 | L14: =IF(AND(E14<Parameters!$B$7,E14>=Parameters!$B$7*(1-Parameters!$B$9)),1,0) -> 0 | M14: =IF(AND(E14<Parameters!$B$7,COUNTIFS($C$5:$C$634,C14,$B$5:$B$634,B14)>1,SUMIFS($E$5:$E$634,$C$5:$C$634,C14,$B$5:$B$634,B14)>=Parameters!$B$7),1,0) -> 0 | N14: =IF(AND(E14>=Parameters!$B$7,F14<>Parameters!$B$8),1,0) -> 0 | O14: =INDEX(Vendor_Benford!$N$6:$N$50,MATCH(C14,Vendor_Benford!$A$6:$A$50,0)) -> 0 | P14: =INDEX(Vendor_Benford!$M$6:$M$50,MATCH(C14,Vendor_Benford!$A$6:$A$50,0)) -> 0 | Q14: =I14*Parameters!$B$28+J14*Parameters!$B$29+K14*Parameters!$B$30+L14*Parameters!$B$31+M14*Parameters!$B$32+N14*Parameters!$B$33+O14*Parameters!$B$34+P14*Parameters!$B$35 -> 0 | R14: =IF(Q14>=Parameters!$B$24,"High","")
A15: P0011 | B15: 45663 | C15: V020 | D15: INV20012 | E15: 2622.95 | F15: FIN_DIR | G15: =VALUE(LEFT(TEXT(E15,"0.00"),1)) -> 2 | H15: =UPPER(SUBSTITUTE(SUBSTITUTE(SUBSTITUTE(D15," ",""),"/",""),".","")) -> INV20012 | I15: =IF(COUNTIFS($C$5:C15,C15,$H$5:H15,H15,$E$5:E15,E15)>1,1,0) -> 0 | J15: =IF(AND(I15=0,COUNTIFS($C$5:$C$634,C15,$E$5:$E$634,E15,$B$5:$B$634,">="&(B15-Parameters!$B$12),$B$5:$B$634,"<="&(B15+Parameters!$B$12),$H$5:$H$634,"<>"&H15)>0),1,0) -> 0 | K15: =IF(AND(E15>=Parameters!$B$11,ROUND(MOD(ROUND(E15,2),Parameters!$B$10),2)=0),1,0) -> 0 | L15: =IF(AND(E15<Parameters!$B$7,E15>=Parameters!$B$7*(1-Parameters!$B$9)),1,0) -> 0 | M15: =IF(AND(E15<Parameters!$B$7,COUNTIFS($C$5:$C$634,C15,$B$5:$B$634,B15)>1,SUMIFS($E$5:$E$634,$C$5:$C$634,C15,$B$5:$B$634,B15)>=Parameters!$B$7),1,0) -> 0 | N15: =IF(AND(E15>=Parameters!$B$7,F15<>Parameters!$B$8),1,0) -> 0 | O15: =INDEX(Vendor_Benford!$N$6:$N$50,MATCH(C15,Vendor_Benford!$A$6:$A$50,0)) -> 0 | P15: =INDEX(Vendor_Benford!$M$6:$M$50,MATCH(C15,Vendor_Benford!$A$6:$A$50,0)) -> 0 | Q15: =I15*Parameters!$B$28+J15*Parameters!$B$29+K15*Parameters!$B$30+L15*Parameters!$B$31+M15*Parameters!$B$32+N15*Parameters!$B$33+O15*Parameters!$B$34+P15*Parameters!$B$35 -> 0 | R15: =IF(Q15>=Parameters!$B$24,"High","")
A16: P0012 | B16: 45664 | C16: V012 | D16: INV12012 | E16: 6340.75 | F16: FIN_DIR | G16: =VALUE(LEFT(TEXT(E16,"0.00"),1)) -> 6 | H16: =UPPER(SUBSTITUTE(SUBSTITUTE(SUBSTITUTE(D16," ",""),"/",""),".","")) -> INV12012 | I16: =IF(COUNTIFS($C$5:C16,C16,$H$5:H16,H16,$E$5:E16,E16)>1,1,0) -> 1 | J16: =IF(AND(I16=0,COUNTIFS($C$5:$C$634,C16,$E$5:$E$634,E16,$B$5:$B$634,">="&(B16-Parameters!$B$12),$B$5:$B$634,"<="&(B16+Parameters!$B$12),$H$5:$H$634,"<>"&H16)>0),1,0) -> 0 | K16: =IF(AND(E16>=Parameters!$B$11,ROUND(MOD(ROUND(E16,2),Parameters!$B$10),2)=0),1,0) -> 0 | L16: =IF(AND(E16<Parameters!$B$7,E16>=Parameters!$B$7*(1-Parameters!$B$9)),1,0) -> 0 | M16: =IF(AND(E16<Parameters!$B$7,COUNTIFS($C$5:$C$634,C16,$B$5:$B$634,B16)>1,SUMIFS($E$5:$E$634,$C$5:$C$634,C16,$B$5:$B$634,B16)>=Parameters!$B$7),1,0) -> 0 | N16: =IF(AND(E16>=Parameters!$B$7,F16<>Parameters!$B$8),1,0) -> 0 | O16: =INDEX(Vendor_Benford!$N$6:$N$50,MATCH(C16,Vendor_Benford!$A$6:$A$50,0)) -> 0 | P16: =INDEX(Vendor_Benford!$M$6:$M$50,MATCH(C16,Vendor_Benford!$A$6:$A$50,0)) -> 0 | Q16: =I16*Parameters!$B$28+J16*Parameters!$B$29+K16*Parameters!$B$30+L16*Parameters!$B$31+M16*Parameters!$B$32+N16*Parameters!$B$33+O16*Parameters!$B$34+P16*Parameters!$B$35 -> 5 | R16: =IF(Q16>=Parameters!$B$24,"High","") -> High
... A634: P0630 | B634: 46022 | C634: V033 | D634: INV33005 | E634: 3185.98 | F634: FIN_DIR | G634: =VALUE(LEFT(TEXT(E634,"0.00"),1)) -> 3 | H634: =UPPER(SUBSTITUTE(SUBSTITUTE(SUBSTITUTE(D634," ",""),"/",""),".","")) -> INV33005 | I634: =IF(COUNTIFS($C$5:C634,C634,$H$5:H634,H634,$E$5:E634,E634)>1,1,0) -> 0 | J634: =IF(AND(I634=0,COUNTIFS($C$5:$C$634,C634,$E$5:$E$634,E634,$B$5:$B$634,">="&(B634-Parameters!$B$12),$B$5:$B$634,"<="&(B634+Parameters!$B$12),$H$5:$H$634,"<>"&H634)>0),1,0) -> 0 | K634: =IF(AND(E634>=Parameters!$B$11,ROUND(MOD(ROUND(E634,2),Parameters!$B$10),2)=0),1,0) -> 0 | L634: =IF(AND(E634<Parameters!$B$7,E634>=Parameters!$B$7*(1-Parameters!$B$9)),1,0) -> 0 | M634: =IF(AND(E634<Parameters!$B$7,COUNTIFS($C$5:$C$634,C634,$B$5:$B$634,B634)>1,SUMIFS($E$5:$E$634,$C$5:$C$634,C634,$B$5:$B$634,B634)>=Parameters!$B$7),1,0) -> 0 | N634: =IF(AND(E634>=Parameters!$B$7,F634<>Parameters!$B$8),1,0) -> 0 | O634: =INDEX(Vendor_Benford!$N$6:$N$50,MATCH(C634,Vendor_Benford!$A$6:$A$50,0)) -> 0 | P634: =INDEX(Vendor_Benford!$M$6:$M$50,MATCH(C634,Vendor_Benford!$A$6:$A$50,0)) -> 0 | Q634: =I634*Parameters!$B$28+J634*Parameters!$B$29+K634*Parameters!$B$30+L634*Parameters!$B$31+M634*Parameters!$B$32+N634*Parameters!$B$33+O634*Parameters!$B$34+P634*Parameters!$B$35 -> 0 | R634: =IF(Q634>=Parameters!$B$24,"High","")

Sheet Benford
A1: Benford's Law, first digit test, all payments
A2: Sample / demonstration data only. No real company, vendor, employee or transaction.
A3: z uses the continuity correction. MAD is the mean absolute deviation across nine digits.
A4: First digit | B4: Count | C4: Actual % | D4: Expected % | E4: Difference | F4: z statistic | G4: Significant at 5 percent? | H4: Chi square term
A5: 1 | B5: =COUNTIF(Payments!$G$5:$G$634,A5) -> 169 | C5: =B5/$B$15 -> 0.26825397 | D5: =LOG10(1+1/A5) -> 0.30103 | E5: =C5-D5 -> -0.032776027 | F5: =MAX(0,ABS(E5)-1/(2*$B$15))/SQRT(D5*(1-D5)/$B$15) -> 1.7500355 | G5: =IF(F5>Parameters!$B$15,"Yes","No") -> No | H5: =$B$15*(C5-D5)^2/D5 -> 2.2482438
A6: 2 | B6: =COUNTIF(Payments!$G$5:$G$634,A6) -> 116 | C6: =B6/$B$15 -> 0.18412698 | D6: =LOG10(1+1/A6) -> 0.17609126 | E6: =C6-D6 -> 0.0080357251 | F6: =MAX(0,ABS(E6)-1/(2*$B$15))/SQRT(D6*(1-D6)/$B$15) -> 0.47722677 | G6: =IF(F6>Parameters!$B$15,"Yes","No") -> No | H6: =$B$15*(C6-D6)^2/D6 -> 0.23102176
A7: 3 | B7: =COUNTIF(Payments!$G$5:$G$634,A7) -> 56 | C7: =B7/$B$15 -> 0.088888889 | D7: =LOG10(1+1/A7) -> 0.12493874 | E7: =C7-D7 -> -0.036049848 | F7: =MAX(0,ABS(E7)-1/(2*$B$15))/SQRT(D7*(1-D7)/$B$15) -> 2.6763195 | G7: =IF(F7>Parameters!$B$15,"Yes","No") -> Yes | H7: =$B$15*(C7-D7)^2/D7 -> 6.553153
A8: 4 | B8: =COUNTIF(Payments!$G$5:$G$634,A8) -> 111 | C8: =B8/$B$15 -> 0.17619048 | D8: =LOG10(1+1/A8) -> 0.096910013 | E8: =C8-D8 -> 0.079280463 | F8: =MAX(0,ABS(E8)-1/(2*$B$15))/SQRT(D8*(1-D8)/$B$15) -> 6.6591244 | G8: =IF(F8>Parameters!$B$15,"Yes","No") -> Yes | H8: =$B$15*(C8-D8)^2/D8 -> 40.860554
A9: 5 | B9: =COUNTIF(Payments!$G$5:$G$634,A9) -> 44 | C9: =B9/$B$15 -> 0.06984127 | D9: =LOG10(1+1/A9) -> 0.079181246 | E9: =C9-D9 -> -0.0093399762 | F9: =MAX(0,ABS(E9)-1/(2*$B$15))/SQRT(D9*(1-D9)/$B$15) -> 0.79442235 | G9: =IF(F9>Parameters!$B$15,"Yes","No") -> No | H9: =$B$15*(C9-D9)^2/D9 -> 0.69408036
A10: 6 | B10: =COUNTIF(Payments!$G$5:$G$634,A10) -> 41 | C10: =B10/$B$15 -> 0.065079365 | D10: =LOG10(1+1/A10) -> 0.06694679 | E10: =C10-D10 -> -0.0018674246 | F10: =MAX(0,ABS(E10)-1/(2*$B$15))/SQRT(D10*(1-D10)/$B$15) -> 0.1078363 | G10: =IF(F10>Parameters!$B$15,"Yes","No") -> No | H10: =$B$15*(C10-D10)^2/D10 -> 0.032816852
A11: 7 | B11: =COUNTIF(Payments!$G$5:$G$634,A11) -> 31 | C11: =B11/$B$15 -> 0.049206349 | D11: =LOG10(1+1/A11) -> 0.057991947 | E11: =C11-D11 -> -0.0087855978 | F11: =MAX(0,ABS(E11)-1/(2*$B$15))/SQRT(D11*(1-D11)/$B$15) -> 0.85824586 | G11: =IF(F11>Parameters!$B$15,"Yes","No") -> No | H11: =$B$15*(C11-D11)^2/D11 -> 0.83852399
A12: 8 | B12: =COUNTIF(Payments!$G$5:$G$634,A12) -> 39 | C12: =B12/$B$15 -> 0.061904762 | D12: =LOG10(1+1/A12) -> 0.051152522 | E12: =C12-D12 -> 0.010752239 | F12: =MAX(0,ABS(E12)-1/(2*$B$15))/SQRT(D12*(1-D12)/$B$15) -> 1.1345832 | G12: =IF(F12>Parameters!$B$15,"Yes","No") -> No | H12: =$B$15*(C12-D12)^2/D12 -> 1.4238733
A13: 9 | B13: =COUNTIF(Payments!$G$5:$G$634,A13) -> 23 | C13: =B13/$B$15 -> 0.036507937 | D13: =LOG10(1+1/A13) -> 0.045757491 | E13: =C13-D13 -> -0.0092495541 | F13: =MAX(0,ABS(E13)-1/(2*$B$15))/SQRT(D13*(1-D13)/$B$15) -> 1.0157102 | G13: =IF(F13>Parameters!$B$15,"Yes","No") -> No | H13: =$B$15*(C13-D13)^2/D13 -> 1.1779312
A15: Total payments (n) | B15: =SUM(B5:B13) -> 630
A16: MAD | B16: =SUMPRODUCT(ABS(E5:E13))/9 -> 0.021792984
A17: Conformity (MAD bands) | B17: =IF(B16<=0.006,"Close conformity",IF(B16<=0.012,"Acceptable conformity",IF(B16<=0.015,"Marginally acceptable conformity","Nonconformity"))) -> Nonconformity
A18: Chi square | B18: =SUM(H5:H13) -> 54.060199
A19: Chi square critical (8 df, 5 percent) | B19: =Parameters!$B$16 -> 15.507
A20: Chi square result | B20: =IF(B18>B19,"Reject conformity","Do not reject") -> Reject conformity
A21: Digits significant at 5 percent | B21: =COUNTIF(G5:G13,"Yes") -> 2

Sheet Vendor_Benford
A1: Vendor level Benford test and employee bank match
A2: Sample / demonstration data only. No real company, vendor, employee or transaction.
A3: Expected proportions in row 5. Flag needs the minimum payment count on the Parameters sheet.
A4: Vendor | B4: Payments (n) | C4: Digit 1 | D4: Digit 2 | E4: Digit 3 | F4: Digit 4 | G4: Digit 5 | H4: Digit 6 | I4: Digit 7 | J4: Digit 8 | K4: Digit 9 | L4: MAD | M4: Benford flag | N4: Employee bank match
A5: Expected | C5: =LOG10(1+1/1) -> 0.30103 | D5: =LOG10(1+1/2) -> 0.17609126 | E5: =LOG10(1+1/3) -> 0.12493874 | F5: =LOG10(1+1/4) -> 0.096910013 | G5: =LOG10(1+1/5) -> 0.079181246 | H5: =LOG10(1+1/6) -> 0.06694679 | I5: =LOG10(1+1/7) -> 0.057991947 | J5: =LOG10(1+1/8) -> 0.051152522 | K5: =LOG10(1+1/9) -> 0.045757491
A6: V001 | B6: =COUNTIF(Payments!$C$5:$C$634,A6) -> 12 | C6: =COUNTIFS(Payments!$C$5:$C$634,$A6,Payments!$G$5:$G$634,1) -> 0 | D6: =COUNTIFS(Payments!$C$5:$C$634,$A6,Payments!$G$5:$G$634,2) -> 0 | E6: =COUNTIFS(Payments!$C$5:$C$634,$A6,Payments!$G$5:$G$634,3) -> 0 | F6: =COUNTIFS(Payments!$C$5:$C$634,$A6,Payments!$G$5:$G$634,4) -> 0 | G6: =COUNTIFS(Payments!$C$5:$C$634,$A6,Payments!$G$5:$G$634,5) -> 0 | H6: =COUNTIFS(Payments!$C$5:$C$634,$A6,Payments!$G$5:$G$634,6) -> 0 | I6: =COUNTIFS(Payments!$C$5:$C$634,$A6,Payments!$G$5:$G$634,7) -> 0 | J6: =COUNTIFS(Payments!$C$5:$C$634,$A6,Payments!$G$5:$G$634,8) -> 12 | K6: =COUNTIFS(Payments!$C$5:$C$634,$A6,Payments!$G$5:$G$634,9) -> 0 | L6: =IF(B6=0,0,SUMPRODUCT(ABS(C6:K6/B6-$C$5:$K$5))/9) -> 0.210855 | M6: =IF(AND(B6>=Parameters!$B$13,L6>Parameters!$B$14),1,0) -> 0 | N6: =IF(COUNTIF(Employees!$B$5:$B$29,INDEX(Vendors!$C$5:$C$49,MATCH(A6,Vendors!$A$5:$A$49,0)))>0,1,0) -> 0
A7: V002 | B7: =COUNTIF(Payments!$C$5:$C$634,A7) -> 12 | C7: =COUNTIFS(Payments!$C$5:$C$634,$A7,Payments!$G$5:$G$634,1) -> 0 | D7: =COUNTIFS(Payments!$C$5:$C$634,$A7,Payments!$G$5:$G$634,2) -> 0 | E7: =COUNTIFS(Payments!$C$5:$C$634,$A7,Payments!$G$5:$G$634,3) -> 0 | F7: =COUNTIFS(Payments!$C$5:$C$634,$A7,Payments!$G$5:$G$634,4) -> 12 | G7: =COUNTIFS(Payments!$C$5:$C$634,$A7,Payments!$G$5:$G$634,5) -> 0 | H7: =COUNTIFS(Payments!$C$5:$C$634,$A7,Payments!$G$5:$G$634,6) -> 0 | I7: =COUNTIFS(Payments!$C$5:$C$634,$A7,Payments!$G$5:$G$634,7) -> 0 | J7: =COUNTIFS(Payments!$C$5:$C$634,$A7,Payments!$G$5:$G$634,8) -> 0 | K7: =COUNTIFS(Payments!$C$5:$C$634,$A7,Payments!$G$5:$G$634,9) -> 0 | L7: =IF(B7=0,0,SUMPRODUCT(ABS(C7:K7/B7-$C$5:$K$5))/9) -> 0.20068666 | M7: =IF(AND(B7>=Parameters!$B$13,L7>Parameters!$B$14),1,0) -> 0 | N7: =IF(COUNTIF(Employees!$B$5:$B$29,INDEX(Vendors!$C$5:$C$49,MATCH(A7,Vendors!$A$5:$A$49,0)))>0,1,0) -> 0
A8: V003 | B8: =COUNTIF(Payments!$C$5:$C$634,A8) -> 16 | C8: =COUNTIFS(Payments!$C$5:$C$634,$A8,Payments!$G$5:$G$634,1) -> 7 | D8: =COUNTIFS(Payments!$C$5:$C$634,$A8,Payments!$G$5:$G$634,2) -> 3 | E8: =COUNTIFS(Payments!$C$5:$C$634,$A8,Payments!$G$5:$G$634,3) -> 2 | F8: =COUNTIFS(Payments!$C$5:$C$634,$A8,Payments!$G$5:$G$634,4) -> 3 | G8: =COUNTIFS(Payments!$C$5:$C$634,$A8,Payments!$G$5:$G$634,5) -> 0 | H8: =COUNTIFS(Payments!$C$5:$C$634,$A8,Payments!$G$5:$G$634,6) -> 1 | I8: =COUNTIFS(Payments!$C$5:$C$634,$A8,Payments!$G$5:$G$634,7) -> 0 | J8: =COUNTIFS(Payments!$C$5:$C$634,$A8,Payments!$G$5:$G$634,8) -> 0 | K8: =COUNTIFS(Payments!$C$5:$C$634,$A8,Payments!$G$5:$G$634,9) -> 0 | L8: =IF(B8=0,0,SUMPRODUCT(ABS(C8:K8/B8-$C$5:$K$5))/9) -> 0.053006666 | M8: =IF(AND(B8>=Parameters!$B$13,L8>Parameters!$B$14),1,0) -> 0 | N8: =IF(COUNTIF(Employees!$B$5:$B$29,INDEX(Vendors!$C$5:$C$49,MATCH(A8,Vendors!$A$5:$A$49,0)))>0,1,0) -> 0
A9: V004 | B9: =COUNTIF(Payments!$C$5:$C$634,A9) -> 10 | C9: =COUNTIFS(Payments!$C$5:$C$634,$A9,Payments!$G$5:$G$634,1) -> 5 | D9: =COUNTIFS(Payments!$C$5:$C$634,$A9,Payments!$G$5:$G$634,2) -> 1 | E9: =COUNTIFS(Payments!$C$5:$C$634,$A9,Payments!$G$5:$G$634,3) -> 0 | F9: =COUNTIFS(Payments!$C$5:$C$634,$A9,Payments!$G$5:$G$634,4) -> 1 | G9: =COUNTIFS(Payments!$C$5:$C$634,$A9,Payments!$G$5:$G$634,5) -> 0 | H9: =COUNTIFS(Payments!$C$5:$C$634,$A9,Payments!$G$5:$G$634,6) -> 1 | I9: =COUNTIFS(Payments!$C$5:$C$634,$A9,Payments!$G$5:$G$634,7) -> 0 | J9: =COUNTIFS(Payments!$C$5:$C$634,$A9,Payments!$G$5:$G$634,8) -> 2 | K9: =COUNTIFS(Payments!$C$5:$C$634,$A9,Payments!$G$5:$G$634,9) -> 0 | L9: =IF(B9=0,0,SUMPRODUCT(ABS(C9:K9/B9-$C$5:$K$5))/9) -> 0.085324595 | M9: =IF(AND(B9>=Parameters!$B$13,L9>Parameters!$B$14),1,0) -> 0 | N9: =IF(COUNTIF(Employees!$B$5:$B$29,INDEX(Vendors!$C$5:$C$49,MATCH(A9,Vendors!$A$5:$A$49,0)))>0,1,0) -> 0
A10: V005 | B10: =COUNTIF(Payments!$C$5:$C$634,A10) -> 18 | C10: =COUNTIFS(Payments!$C$5:$C$634,$A10,Payments!$G$5:$G$634,1) -> 4 | D10: =COUNTIFS(Payments!$C$5:$C$634,$A10,Payments!$G$5:$G$634,2) -> 6 | E10: =COUNTIFS(Payments!$C$5:$C$634,$A10,Payments!$G$5:$G$634,3) -> 5 | F10: =COUNTIFS(Payments!$C$5:$C$634,$A10,Payments!$G$5:$G$634,4) -> 0 | G10: =COUNTIFS(Payments!$C$5:$C$634,$A10,Payments!$G$5:$G$634,5) -> 2 | H10: =COUNTIFS(Payments!$C$5:$C$634,$A10,Payments!$G$5:$G$634,6) -> 0 | I10: =COUNTIFS(Payments!$C$5:$C$634,$A10,Payments!$G$5:$G$634,7) -> 0 | J10: =COUNTIFS(Payments!$C$5:$C$634,$A10,Payments!$G$5:$G$634,8) -> 0 | K10: =COUNTIFS(Payments!$C$5:$C$634,$A10,Payments!$G$5:$G$634,9) -> 1 | L10: =IF(B10=0,0,SUMPRODUCT(ABS(C10:K10/B10-$C$5:$K$5))/9) -> 0.078179788 | M10: =IF(AND(B10>=Parameters!$B$13,L10>Parameters!$B$14),1,0) -> 0 | N10: =IF(COUNTIF(Employees!$B$5:$B$29,INDEX(Vendors!$C$5:$C$49,MATCH(A10,Vendors!$A$5:$A$49,0)))>0,1,0) -> 0
A11: V006 | B11: =COUNTIF(Payments!$C$5:$C$634,A11) -> 8 | C11: =COUNTIFS(Payments!$C$5:$C$634,$A11,Payments!$G$5:$G$634,1) -> 2 | D11: =COUNTIFS(Payments!$C$5:$C$634,$A11,Payments!$G$5:$G$634,2) -> 1 | E11: =COUNTIFS(Payments!$C$5:$C$634,$A11,Payments!$G$5:$G$634,3) -> 1 | F11: =COUNTIFS(Payments!$C$5:$C$634,$A11,Payments!$G$5:$G$634,4) -> 0 | G11: =COUNTIFS(Payments!$C$5:$C$634,$A11,Payments!$G$5:$G$634,5) -> 1 | H11: =COUNTIFS(Payments!$C$5:$C$634,$A11,Payments!$G$5:$G$634,6) -> 0 | I11: =COUNTIFS(Payments!$C$5:$C$634,$A11,Payments!$G$5:$G$634,7) -> 0 | J11: =COUNTIFS(Payments!$C$5:$C$634,$A11,Payments!$G$5:$G$634,8) -> 2 | K11: =COUNTIFS(Payments!$C$5:$C$634,$A11,Payments!$G$5:$G$634,9) -> 1 | L11: =IF(B11=0,0,SUMPRODUCT(ABS(C11:K11/B11-$C$5:$K$5))/9) -> 0.071993334 | M11: =IF(AND(B11>=Parameters!$B$13,L11>Parameters!$B$14),1,0) -> 0 | N11: =IF(COUNTIF(Employees!$B$5:$B$29,INDEX(Vendors!$C$5:$C$49,MATCH(A11,Vendors!$A$5:$A$49,0)))>0,1,0) -> 0
A12: V007 | B12: =COUNTIF(Payments!$C$5:$C$634,A12) -> 16 | C12: =COUNTIFS(Payments!$C$5:$C$634,$A12,Payments!$G$5:$G$634,1) -> 5 | D12: =COUNTIFS(Payments!$C$5:$C$634,$A12,Payments!$G$5:$G$634,2) -> 5 | E12: =COUNTIFS(Payments!$C$5:$C$634,$A12,Payments!$G$5:$G$634,3) -> 2 | F12: =COUNTIFS(Payments!$C$5:$C$634,$A12,Payments!$G$5:$G$634,4) -> 1 | G12: =COUNTIFS(Payments!$C$5:$C$634,$A12,Payments!$G$5:$G$634,5) -> 0 | H12: =COUNTIFS(Payments!$C$5:$C$634,$A12,Payments!$G$5:$G$634,6) -> 2 | I12: =COUNTIFS(Payments!$C$5:$C$634,$A12,Payments!$G$5:$G$634,7) -> 1 | J12: =COUNTIFS(Payments!$C$5:$C$634,$A12,Payments!$G$5:$G$634,8) -> 0 | K12: =COUNTIFS(Payments!$C$5:$C$634,$A12,Payments!$G$5:$G$634,9) -> 0 | L12: =IF(B12=0,0,SUMPRODUCT(ABS(C12:K12/B12-$C$5:$K$5))/9) -> 0.04677806 | M12: =IF(AND(B12>=Parameters!$B$13,L12>Parameters!$B$14),1,0) -> 0 | N12: =IF(COUNTIF(Employees!$B$5:$B$29,INDEX(Vendors!$C$5:$C$49,MATCH(A12,Vendors!$A$5:$A$49,0)))>0,1,0) -> 0
A13: V008 | B13: =COUNTIF(Payments!$C$5:$C$634,A13) -> 16 | C13: =COUNTIFS(Payments!$C$5:$C$634,$A13,Payments!$G$5:$G$634,1) -> 4 | D13: =COUNTIFS(Payments!$C$5:$C$634,$A13,Payments!$G$5:$G$634,2) -> 4 | E13: =COUNTIFS(Payments!$C$5:$C$634,$A13,Payments!$G$5:$G$634,3) -> 3 | F13: =COUNTIFS(Payments!$C$5:$C$634,$A13,Payments!$G$5:$G$634,4) -> 2 | G13: =COUNTIFS(Payments!$C$5:$C$634,$A13,Payments!$G$5:$G$634,5) -> 1 | H13: =COUNTIFS(Payments!$C$5:$C$634,$A13,Payments!$G$5:$G$634,6) -> 0 | I13: =COUNTIFS(Payments!$C$5:$C$634,$A13,Payments!$G$5:$G$634,7) -> 1 | J13: =COUNTIFS(Payments!$C$5:$C$634,$A13,Payments!$G$5:$G$634,8) -> 1 | K13: =COUNTIFS(Payments!$C$5:$C$634,$A13,Payments!$G$5:$G$634,9) -> 0 | L13: =IF(B13=0,0,SUMPRODUCT(ABS(C13:K13/B13-$C$5:$K$5))/9) -> 0.040092338 | M13: =IF(AND(B13>=Parameters!$B$13,L13>Parameters!$B$14),1,0) -> 0 | N13: =IF(COUNTIF(Employees!$B$5:$B$29,INDEX(Vendors!$C$5:$C$49,MATCH(A13,Vendors!$A$5:$A$49,0)))>0,1,0) -> 0
A14: V009 | B14: =COUNTIF(Payments!$C$5:$C$634,A14) -> 27 | C14: =COUNTIFS(Payments!$C$5:$C$634,$A14,Payments!$G$5:$G$634,1) -> 7 | D14: =COUNTIFS(Payments!$C$5:$C$634,$A14,Payments!$G$5:$G$634,2) -> 8 | E14: =COUNTIFS(Payments!$C$5:$C$634,$A14,Payments!$G$5:$G$634,3) -> 4 | F14: =COUNTIFS(Payments!$C$5:$C$634,$A14,Payments!$G$5:$G$634,4) -> 3 | G14: =COUNTIFS(Payments!$C$5:$C$634,$A14,Payments!$G$5:$G$634,5) -> 1 | H14: =COUNTIFS(Payments!$C$5:$C$634,$A14,Payments!$G$5:$G$634,6) -> 2 | I14: =COUNTIFS(Payments!$C$5:$C$634,$A14,Payments!$G$5:$G$634,7) -> 1 | J14: =COUNTIFS(Payments!$C$5:$C$634,$A14,Payments!$G$5:$G$634,8) -> 0 | K14: =COUNTIFS(Payments!$C$5:$C$634,$A14,Payments!$G$5:$G$634,9) -> 1 | L14: =IF(B14=0,0,SUMPRODUCT(ABS(C14:K14/B14-$C$5:$K$5))/9) -> 0.036609518 | M14: =IF(AND(B14>=Parameters!$B$13,L14>Parameters!$B$14),1,0) -> 0 | N14: =IF(COUNTIF(Employees!$B$5:$B$29,INDEX(Vendors!$C$5:$C$49,MATCH(A14,Vendors!$A$5:$A$49,0)))>0,1,0) -> 0
A15: V010 | B15: =COUNTIF(Payments!$C$5:$C$634,A15) -> 7 | C15: =COUNTIFS(Payments!$C$5:$C$634,$A15,Payments!$G$5:$G$634,1) -> 1 | D15: =COUNTIFS(Payments!$C$5:$C$634,$A15,Payments!$G$5:$G$634,2) -> 2 | E15: =COUNTIFS(Payments!$C$5:$C$634,$A15,Payments!$G$5:$G$634,3) -> 1 | F15: =COUNTIFS(Payments!$C$5:$C$634,$A15,Payments!$G$5:$G$634,4) -> 2 | G15: =COUNTIFS(Payments!$C$5:$C$634,$A15,Payments!$G$5:$G$634,5) -> 1 | H15: =COUNTIFS(Payments!$C$5:$C$634,$A15,Payments!$G$5:$G$634,6) -> 0 | I15: =COUNTIFS(Payments!$C$5:$C$634,$A15,Payments!$G$5:$G$634,7) -> 0 | J15: =COUNTIFS(Payments!$C$5:$C$634,$A15,Payments!$G$5:$G$634,8) -> 0 | K15: =COUNTIFS(Payments!$C$5:$C$634,$A15,Payments!$G$5:$G$634,9) -> 0 | L15: =IF(B15=0,0,SUMPRODUCT(ABS(C15:K15/B15-$C$5:$K$5))/9) -> 0.084449245 | M15: =IF(AND(B15>=Parameters!$B$13,L15>Parameters!$B$14),1,0) -> 0 | N15: =IF(COUNTIF(Employees!$B$5:$B$29,INDEX(Vendors!$C$5:$C$49,MATCH(A15,Vendors!$A$5:$A$49,0)))>0,1,0) -> 0
A16: V011 | B16: =COUNTIF(Payments!$C$5:$C$634,A16) -> 20 | C16: =COUNTIFS(Payments!$C$5:$C$634,$A16,Payments!$G$5:$G$634,1) -> 8 | D16: =COUNTIFS(Payments!$C$5:$C$634,$A16,Payments!$G$5:$G$634,2) -> 3 | E16: =COUNTIFS(Payments!$C$5:$C$634,$A16,Payments!$G$5:$G$634,3) -> 0 | F16: =COUNTIFS(Payments!$C$5:$C$634,$A16,Payments!$G$5:$G$634,4) -> 2 | G16: =COUNTIFS(Payments!$C$5:$C$634,$A16,Payments!$G$5:$G$634,5) -> 1 | H16: =COUNTIFS(Payments!$C$5:$C$634,$A16,Payments!$G$5:$G$634,6) -> 0 | I16: =COUNTIFS(Payments!$C$5:$C$634,$A16,Payments!$G$5:$G$634,7) -> 2 | J16: =COUNTIFS(Payments!$C$5:$C$634,$A16,Payments!$G$5:$G$634,8) -> 2 | K16: =COUNTIFS(Payments!$C$5:$C$634,$A16,Payments!$G$5:$G$634,9) -> 2 | L16: =IF(B16=0,0,SUMPRODUCT(ABS(C16:K16/B16-$C$5:$K$5))/9) -> 0.054924007 | M16: =IF(AND(B16>=Parameters!$B$13,L16>Parameters!$B$14),1,0) -> 0 | N16: =IF(COUNTIF(Employees!$B$5:$B$29,INDEX(Vendors!$C$5:$C$49,MATCH(A16,Vendors!$A$5:$A$49,0)))>0,1,0) -> 0
A17: V012 | B17: =COUNTIF(Payments!$C$5:$C$634,A17) -> 24 | C17: =COUNTIFS(Payments!$C$5:$C$634,$A17,Payments!$G$5:$G$634,1) -> 6 | D17: =COUNTIFS(Payments!$C$5:$C$634,$A17,Payments!$G$5:$G$634,2) -> 4 | E17: =COUNTIFS(Payments!$C$5:$C$634,$A17,Payments!$G$5:$G$634,3) -> 3 | F17: =COUNTIFS(Payments!$C$5:$C$634,$A17,Payments!$G$5:$G$634,4) -> 2 | G17: =COUNTIFS(Payments!$C$5:$C$634,$A17,Payments!$G$5:$G$634,5) -> 1 | H17: =COUNTIFS(Payments!$C$5:$C$634,$A17,Payments!$G$5:$G$634,6) -> 4 | I17: =COUNTIFS(Payments!$C$5:$C$634,$A17,Payments!$G$5:$G$634,7) -> 3 | J17: =COUNTIFS(Payments!$C$5:$C$634,$A17,Payments!$G$5:$G$634,8) -> 0 | K17: =COUNTIFS(Payments!$C$5:$C$634,$A17,Payments!$G$5:$G$634,9) -> 1 | L17: =IF(B17=0,0,SUMPRODUCT(ABS(C17:K17/B17-$C$5:$K$5))/9) -> 0.037064265 | M17: =IF(AND(B17>=Parameters!$B$13,L17>Parameters!$B$14),1,0) -> 0 | N17: =IF(COUNTIF(Employees!$B$5:$B$29,INDEX(Vendors!$C$5:$C$49,MATCH(A17,Vendors!$A$5:$A$49,0)))>0,1,0) -> 0
... A50: V045 | B50: =COUNTIF(Payments!$C$5:$C$634,A50) -> 11 | C50: =COUNTIFS(Payments!$C$5:$C$634,$A50,Payments!$G$5:$G$634,1) -> 5 | D50: =COUNTIFS(Payments!$C$5:$C$634,$A50,Payments!$G$5:$G$634,2) -> 2 | E50: =COUNTIFS(Payments!$C$5:$C$634,$A50,Payments!$G$5:$G$634,3) -> 1 | F50: =COUNTIFS(Payments!$C$5:$C$634,$A50,Payments!$G$5:$G$634,4) -> 0 | G50: =COUNTIFS(Payments!$C$5:$C$634,$A50,Payments!$G$5:$G$634,5) -> 0 | H50: =COUNTIFS(Payments!$C$5:$C$634,$A50,Payments!$G$5:$G$634,6) -> 0 | I50: =COUNTIFS(Payments!$C$5:$C$634,$A50,Payments!$G$5:$G$634,7) -> 1 | J50: =COUNTIFS(Payments!$C$5:$C$634,$A50,Payments!$G$5:$G$634,8) -> 1 | K50: =COUNTIFS(Payments!$C$5:$C$634,$A50,Payments!$G$5:$G$634,9) -> 1 | L50: =IF(B50=0,0,SUMPRODUCT(ABS(C50:K50/B50-$C$5:$K$5))/9) -> 0.061570599 | M50: =IF(AND(B50>=Parameters!$B$13,L50>Parameters!$B$14),1,0) -> 0 | N50: =IF(COUNTIF(Employees!$B$5:$B$29,INDEX(Vendors!$C$5:$C$49,MATCH(A50,Vendors!$A$5:$A$49,0)))>0,1,0) -> 0

Sheet COA
A1: Chart of accounts
A2: Sample / demonstration data only. No real company, vendor, employee or transaction.
A3: Synthetic.
A4: Account | B4: Name | C4: Class
A5: 1000 | B5: Cash at bank | C5: Asset
A6: 1100 | B6: Trade receivables | C6: Asset
A7: 1200 | B7: Inventory | C7: Asset
A8: 1500 | B8: Fixed assets | C8: Asset
A9: 2000 | B9: Trade payables | C9: Liability
A10: 2100 | B10: Accruals | C10: Liability
A11: 2500 | B11: Loans | C11: Liability
A12: 4000 | B12: Sales revenue | C12: Revenue
A13: 4100 | B13: Other income | C13: Revenue
A14: 5000 | B14: Cost of sales | C14: Expense
A15: 6000 | B15: Salaries | C15: Expense
A16: 6100 | B16: Rent | C16: Expense
... A19: 9999 | B19: Suspense | C19: Suspense

Sheet JE_Lines
A1: Journal entry lines
A2: Sample / demonstration data only. No real company, vendor, employee or transaction.
A3: Inputs in blue. Class is a formula.
A4: Line ID | B4: JE no | C4: Posting date | D4: Document date | E4: Account | F4: Class | G4: Debit (USD) | H4: Credit (USD) | I4: User | J4: Source | K4: Description
A5: L00001 | B5: 1001 | C5: 45658 | D5: 45657 | E5: 1000 | F5: =INDEX(COA!$C$5:$C$19,MATCH(E5,COA!$A$5:$A$19,0)) -> Asset | G5: 4474.19 | H5: 0 | I5: SYS_AR | J5: System | K5: Customer receipts
A6: L00002 | B6: 1001 | C6: 45658 | D6: 45657 | E6: 1100 | F6: =INDEX(COA!$C$5:$C$19,MATCH(E6,COA!$A$5:$A$19,0)) -> Asset | G6: 0 | H6: 4474.19 | I6: SYS_AR | J6: System | K6: Customer receipts
A7: L00003 | B7: 1002 | C7: 45658 | D7: 45656 | E7: 1100 | F7: =INDEX(COA!$C$5:$C$19,MATCH(E7,COA!$A$5:$A$19,0)) -> Asset | G7: 2895.32 | H7: 0 | I7: SYS_AR | J7: System | K7: Sales invoice batch
A8: L00004 | B8: 1002 | C8: 45658 | D8: 45656 | E8: 4000 | F8: =INDEX(COA!$C$5:$C$19,MATCH(E8,COA!$A$5:$A$19,0)) -> Revenue | G8: 0 | H8: 2895.32 | I8: SYS_AR | J8: System | K8: Sales invoice batch
A9: L00005 | B9: 1003 | C9: 45658 | D9: 45655 | E9: 1100 | F9: =INDEX(COA!$C$5:$C$19,MATCH(E9,COA!$A$5:$A$19,0)) -> Asset | G9: 9816.58 | H9: 0 | I9: SYS_AR | J9: System | K9: Sales invoice batch
A10: L00006 | B10: 1003 | C10: 45658 | D10: 45655 | E10: 1100 | F10: =INDEX(COA!$C$5:$C$19,MATCH(E10,COA!$A$5:$A$19,0)) -> Asset | G10: 4207.11 | H10: 0 | I10: SYS_AR | J10: System | K10: Sales invoice batch
A11: L00007 | B11: 1003 | C11: 45658 | D11: 45655 | E11: 4000 | F11: =INDEX(COA!$C$5:$C$19,MATCH(E11,COA!$A$5:$A$19,0)) -> Revenue | G11: 0 | H11: 14023.69 | I11: SYS_AR | J11: System | K11: Sales invoice batch
A12: L00008 | B12: 1004 | C12: 45659 | D12: 45657 | E12: 1100 | F12: =INDEX(COA!$C$5:$C$19,MATCH(E12,COA!$A$5:$A$19,0)) -> Asset | G12: 1008.74 | H12: 0 | I12: SYS_AR | J12: System | K12: Sales invoice batch
A13: L00009 | B13: 1004 | C13: 45659 | D13: 45657 | E13: 4000 | F13: =INDEX(COA!$C$5:$C$19,MATCH(E13,COA!$A$5:$A$19,0)) -> Revenue | G13: 0 | H13: 1008.74 | I13: SYS_AR | J13: System | K13: Sales invoice batch
A14: L00010 | B14: 1005 | C14: 45659 | D14: 45656 | E14: 6900 | F14: =INDEX(COA!$C$5:$C$19,MATCH(E14,COA!$A$5:$A$19,0)) -> Expense | G14: 233.11 | H14: 0 | I14: FIN02 | J14: Manual | K14: Accrual for sundry costs
A15: L00011 | B15: 1005 | C15: 45659 | D15: 45656 | E15: 2100 | F15: =INDEX(COA!$C$5:$C$19,MATCH(E15,COA!$A$5:$A$19,0)) -> Liability | G15: 0 | H15: 233.11 | I15: FIN02 | J15: Manual | K15: Accrual for sundry costs
A16: L00012 | B16: 1006 | C16: 45659 | D16: 45659 | E16: 6900 | F16: =INDEX(COA!$C$5:$C$19,MATCH(E16,COA!$A$5:$A$19,0)) -> Expense | G16: 37000 | H16: 0 | I16: FIN01 | J16: Manual | K16: Round accrual 3
... A77: L00073 | B77: 1032 | C77: 45674 | D77: 45672 | E77: 2000 | F77: =INDEX(COA!$C$5:$C$19,MATCH(E77,COA!$A$5:$A$19,0)) -> Liability | G77: 0 | H77: 12219.41 | I77: SYS_AP | J77: System | K77: Supplier invoices
A78: L00074 | B78: 1033 | C78: 45674 | D78: 45674 | E78: 6900 | F78: =INDEX(COA!$C$5:$C$19,MATCH(E78,COA!$A$5:$A$19,0)) -> Expense | G78: 34428.78 | H78: 0 | I78: FIN03 | J78: Manual
A79: L00075 | B79: 1033 | C79: 45674 | D79: 45674 | E79: 2100 | F79: =INDEX(COA!$C$5:$C$19,MATCH(E79,COA!$A$5:$A$19,0)) -> Liability | G79: 0 | H79: 34428.78 | I79: FIN03 | J79: Manual
A80: L00076 | B80: 1034 | C80: 45674 | D80: 45670 | E80: 6900 | F80: =INDEX(COA!$C$5:$C$19,MATCH(E80,COA!$A$5:$A$19,0)) -> Expense | G80: 71785.26 | H80: 0 | I80: FIN01 | J80: Manual | K80: Accrual for sundry costs
A81: L00077 | B81: 1034 | C81: 45674 | D81: 45670 | E81: 2100 | F81: =INDEX(COA!$C$5:$C$19,MATCH(E81,COA!$A$5:$A$19,0)) -> Liability | G81: 0 | H81: 71785.26 | I81: FIN01 | J81: Manual | K81: Accrual for sundry costs
A82: L00078 | B82: 1035 | C82: 45674 | D82: 45672 | E82: 1000 | F82: =INDEX(COA!$C$5:$C$19,MATCH(E82,COA!$A$5:$A$19,0)) -> Asset | G82: 111700.56 | H82: 0 | I82: SYS_AR | J82: System | K82: Customer receipts
A83: L00079 | B83: 1035 | C83: 45674 | D83: 45672 | E83: 1100 | F83: =INDEX(COA!$C$5:$C$19,MATCH(E83,COA!$A$5:$A$19,0)) -> Asset | G83: 0 | H83: 111700.56 | I83: SYS_AR | J83: System | K83: Customer receipts
A84: L00080 | B84: 1036 | C84: 45674 | D84: 45670 | E84: 5000 | F84: =INDEX(COA!$C$5:$C$19,MATCH(E84,COA!$A$5:$A$19,0)) -> Expense | G84: 9230.62 | H84: 0 | I84: SYS_AR | J84: System | K84: Cost of sales posting
A85: L00081 | B85: 1036 | C85: 45674 | D85: 45670 | E85: 1200 | F85: =INDEX(COA!$C$5:$C$19,MATCH(E85,COA!$A$5:$A$19,0)) -> Asset | G85: 0 | H85: 9230.62 | I85: SYS_AR | J85: System | K85: Cost of sales posting
A86: L00082 | B86: 1037 | C86: 45674 | D86: 45674 | E86: 5000 | F86: =INDEX(COA!$C$5:$C$19,MATCH(E86,COA!$A$5:$A$19,0)) -> Expense | G86: 4993.54 | H86: 0 | I86: SYS_AR | J86: System | K86: Cost of sales posting
A87: L00083 | B87: 1037 | C87: 45674 | D87: 45674 | E87: 1200 | F87: =INDEX(COA!$C$5:$C$19,MATCH(E87,COA!$A$5:$A$19,0)) -> Asset | G87: 0 | H87: 4993.54 | I87: SYS_AR | J87: System | K87: Cost of sales posting
A88: L00084 | B88: 1038 | C88: 45675 | D88: 45672 | E88: 2000 | F88: =INDEX(COA!$C$5:$C$19,MATCH(E88,COA!$A$5:$A$19,0)) -> Liability | G88: 27029.59 | H88: 0 | I88: SYS_PAY | J88: System | K88: Supplier payments
A89: L00085 | B89: 1038 | C89: 45675 | D89: 45672 | E89: 1000 | F89: =INDEX(COA!$C$5:$C$19,MATCH(E89,COA!$A$5:$A$19,0)) -> Asset | G89: 0 | H89: 27029.59 | I89: SYS_PAY | J89: System | K89: Supplier payments
A90: L00086 | B90: 1039 | C90: 45677 | D90: 45676 | E90: 1000 | F90: =INDEX(COA!$C$5:$C$19,MATCH(E90,COA!$A$5:$A$19,0)) -> Asset | G90: 558.57 | H90: 0 | I90: SYS_AR | J90: System | K90: Customer receipts
A91: L00087 | B91: 1039 | C91: 45677 | D91: 45676 | E91: 1000 | F91: =INDEX(COA!$C$5:$C$19,MATCH(E91,COA!$A$5:$A$19,0)) -> Asset | G91: 239.39 | H91: 0 | I91: SYS_AR | J91: System | K91: Customer receipts
... A120: L00116 | B120: 1052 | C120: 45680 | D120: 45678 | E120: 1100 | F120: =INDEX(COA!$C$5:$C$19,MATCH(E120,COA!$A$5:$A$19,0)) -> Asset | G120: 0 | H120: 70722.06 | I120: SYS_AR | J120: System | K120: Customer receipts
A121: L00117 | B121: 1053 | C121: 45680 | D121: 45680 | E121: 1000 | F121: =INDEX(COA!$C$5:$C$19,MATCH(E121,COA!$A$5:$A$19,0)) -> Asset | G121: 44483.01 | H121: 0 | I121: SYS_AR | J121: System
A122: L00118 | B122: 1053 | C122: 45680 | D122: 45680 | E122: 1100 | F122: =INDEX(COA!$C$5:$C$19,MATCH(E122,COA!$A$5:$A$19,0)) -> Asset | G122: 0 | H122: 44483.01 | I122: SYS_AR | J122: System
A123: L00119 | B123: 1054 | C123: 45681 | D123: 45678 | E123: 1100 | F123: =INDEX(COA!$C$5:$C$19,MATCH(E123,COA!$A$5:$A$19,0)) -> Asset | G123: 1513.51 | H123: 0 | I123: SYS_AR | J123: System | K123: Sales invoice batch
A124: L00120 | B124: 1054 | C124: 45681 | D124: 45678 | E124: 4000 | F124: =INDEX(COA!$C$5:$C$19,MATCH(E124,COA!$A$5:$A$19,0)) -> Revenue | G124: 0 | H124: 1513.51 | I124: SYS_AR | J124: System | K124: Sales invoice batch
A125: L00121 | B125: 1055 | C125: 45681 | D125: 45681 | E125: 2100 | F125: =INDEX(COA!$C$5:$C$19,MATCH(E125,COA!$A$5:$A$19,0)) -> Liability | G125: 366.88 | H125: 0 | I125: FIN05 | J125: Manual | K125: Accrual reversal
A126: L00122 | B126: 1055 | C126: 45681 | D126: 45681 | E126: 6900 | F126: =INDEX(COA!$C$5:$C$19,MATCH(E126,COA!$A$5:$A$19,0)) -> Expense | G126: 0 | H126: 366.88 | I126: FIN05 | J126: Manual | K126: Accrual reversal
A127: L00123 | B127: 1056 | C127: 45681 | D127: 45678 | E127: 1100 | F127: =INDEX(COA!$C$5:$C$19,MATCH(E127,COA!$A$5:$A$19,0)) -> Asset | G127: 824.81 | H127: 0 | I127: SYS_AR | J127: System | K127: Sales invoice batch
A128: L00124 | B128: 1056 | C128: 45681 | D128: 45678 | E128: 4000 | F128: =INDEX(COA!$C$5:$C$19,MATCH(E128,COA!$A$5:$A$19,0)) -> Revenue | G128: 0 | H128: 824.81 | I128: SYS_AR | J128: System | K128: Sales invoice batch
...

Sheet JE_Entries
A1: Journal entry tests, one row per entry
A2: Sample / demonstration data only. No real company, vendor, employee or transaction.
A3: JE number is from the engine (brown). All other columns are formulas.
A4: JE no | B4: Lines | C4: Total debit | D4: Total credit | E4: Debit less credit | F4: Posting date | G4: Document date | H4: User | I4: Source | J4: Description | K4: Lag (days) | L4: Revenue lines | M4: Suspense lines | N4: Unbalanced | O4: Weekend | P4: Late posting | Q4: Year end window | R4: Unauthorised user | S4: Manual to revenue | T4: Round total | U4: No description | V4: Below limit | W4: Manual to suspense | X4: Sequence gap | Y4: Risk score | Z4: Priority
A5: 1001 | B5: =COUNTIF(JE_Lines!$B$5:$B$1733,A5) -> 2 | C5: =SUMIFS(JE_Lines!$G$5:$G$1733,JE_Lines!$B$5:$B$1733,A5) -> 4474.19 | D5: =SUMIFS(JE_Lines!$H$5:$H$1733,JE_Lines!$B$5:$B$1733,A5) -> 4474.19 | E5: =C5-D5 -> 0 | F5: =INDEX(JE_Lines!$C$5:$C$1733,MATCH(A5,JE_Lines!$B$5:$B$1733,0)) -> 45658 | G5: =INDEX(JE_Lines!$D$5:$D$1733,MATCH(A5,JE_Lines!$B$5:$B$1733,0)) -> 45657 | H5: =INDEX(JE_Lines!$I$5:$I$1733,MATCH(A5,JE_Lines!$B$5:$B$1733,0)) -> SYS_AR | I5: =INDEX(JE_Lines!$J$5:$J$1733,MATCH(A5,JE_Lines!$B$5:$B$1733,0)) -> System | J5: =IF(LEN(INDEX(JE_Lines!$K$5:$K$1733,MATCH(A5,JE_Lines!$B$5:$B$1733,0)))=0,"",INDEX(JE_Lines!$K$5:$K$1733,MATCH(A5,JE_Lines!$B$5:$B$1733,0))) -> Customer receipts | K5: =F5-G5 -> 1 | L5: =COUNTIFS(JE_Lines!$B$5:$B$1733,A5,JE_Lines!$F$5:$F$1733,"Revenue") -> 0 | M5: =COUNTIFS(JE_Lines!$B$5:$B$1733,A5,JE_Lines!$F$5:$F$1733,"Suspense") -> 0 | N5: =IF(ABS(E5)>Parameters!$B$23,1,0) -> 0 | O5: =IF(WEEKDAY(F5,2)>5,1,0) -> 0 | P5: =IF(K5>Parameters!$B$17,1,0) -> 0 | Q5: =IF(AND(F5<=Parameters!$B$6,F5>Parameters!$B$6-Parameters!$B$18),1,0) -> 0 | R5: =IF(COUNTIF(Parameters!$A$51:$A$58,H5)=0,1,0) -> 0 | S5: =IF(AND(I5="Manual",L5>0),1,0) -> 0 | T5: =IF(AND(C5>=Parameters!$B$22,ROUND(MOD(ROUND(C5,2),Parameters!$B$21),2)=0),1,0) -> 0 | U5: =IF(LEN(TRIM(J5))=0,1,0) -> 0 | V5: =IF(AND(I5="Manual",C5<Parameters!$B$19,C5>=Parameters!$B$19*(1-Parameters!$B$20)),1,0) -> 0 | W5: =IF(AND(I5="Manual",M5>0),1,0) -> 0 | X5: =0 -> 0 | Y5: =N5*Parameters!$B$38+O5*Parameters!$B$39+P5*Parameters!$B$40+Q5*Parameters!$B$41+R5*Parameters!$B$42+S5*Parameters!$B$43+T5*Parameters!$B$44+U5*Parameters!$B$45+V5*Parameters!$B$46+W5*Parameters!$B$47+X5*Parameters!$B$48 -> 0 | Z5: =IF(Y5>=Parameters!$B$25,"High","")
A6: 1002 | B6: =COUNTIF(JE_Lines!$B$5:$B$1733,A6) -> 2 | C6: =SUMIFS(JE_Lines!$G$5:$G$1733,JE_Lines!$B$5:$B$1733,A6) -> 2895.32 | D6: =SUMIFS(JE_Lines!$H$5:$H$1733,JE_Lines!$B$5:$B$1733,A6) -> 2895.32 | E6: =C6-D6 -> 0 | F6: =INDEX(JE_Lines!$C$5:$C$1733,MATCH(A6,JE_Lines!$B$5:$B$1733,0)) -> 45658 | G6: =INDEX(JE_Lines!$D$5:$D$1733,MATCH(A6,JE_Lines!$B$5:$B$1733,0)) -> 45656 | H6: =INDEX(JE_Lines!$I$5:$I$1733,MATCH(A6,JE_Lines!$B$5:$B$1733,0)) -> SYS_AR | I6: =INDEX(JE_Lines!$J$5:$J$1733,MATCH(A6,JE_Lines!$B$5:$B$1733,0)) -> System | J6: =IF(LEN(INDEX(JE_Lines!$K$5:$K$1733,MATCH(A6,JE_Lines!$B$5:$B$1733,0)))=0,"",INDEX(JE_Lines!$K$5:$K$1733,MATCH(A6,JE_Lines!$B$5:$B$1733,0))) -> Sales invoice batch | K6: =F6-G6 -> 2 | L6: =COUNTIFS(JE_Lines!$B$5:$B$1733,A6,JE_Lines!$F$5:$F$1733,"Revenue") -> 1 | M6: =COUNTIFS(JE_Lines!$B$5:$B$1733,A6,JE_Lines!$F$5:$F$1733,"Suspense") -> 0 | N6: =IF(ABS(E6)>Parameters!$B$23,1,0) -> 0 | O6: =IF(WEEKDAY(F6,2)>5,1,0) -> 0 | P6: =IF(K6>Parameters!$B$17,1,0) -> 0 | Q6: =IF(AND(F6<=Parameters!$B$6,F6>Parameters!$B$6-Parameters!$B$18),1,0) -> 0 | R6: =IF(COUNTIF(Parameters!$A$51:$A$58,H6)=0,1,0) -> 0 | S6: =IF(AND(I6="Manual",L6>0),1,0) -> 0 | T6: =IF(AND(C6>=Parameters!$B$22,ROUND(MOD(ROUND(C6,2),Parameters!$B$21),2)=0),1,0) -> 0 | U6: =IF(LEN(TRIM(J6))=0,1,0) -> 0 | V6: =IF(AND(I6="Manual",C6<Parameters!$B$19,C6>=Parameters!$B$19*(1-Parameters!$B$20)),1,0) -> 0 | W6: =IF(AND(I6="Manual",M6>0),1,0) -> 0 | X6: =IF(A6-A5>1,1,0) -> 0 | Y6: =N6*Parameters!$B$38+O6*Parameters!$B$39+P6*Parameters!$B$40+Q6*Parameters!$B$41+R6*Parameters!$B$42+S6*Parameters!$B$43+T6*Parameters!$B$44+U6*Parameters!$B$45+V6*Parameters!$B$46+W6*Parameters!$B$47+X6*Parameters!$B$48 -> 0 | Z6: =IF(Y6>=Parameters!$B$25,"High","")
A7: 1003 | B7: =COUNTIF(JE_Lines!$B$5:$B$1733,A7) -> 3 | C7: =SUMIFS(JE_Lines!$G$5:$G$1733,JE_Lines!$B$5:$B$1733,A7) -> 14023.69 | D7: =SUMIFS(JE_Lines!$H$5:$H$1733,JE_Lines!$B$5:$B$1733,A7) -> 14023.69 | E7: =C7-D7 -> 0 | F7: =INDEX(JE_Lines!$C$5:$C$1733,MATCH(A7,JE_Lines!$B$5:$B$1733,0)) -> 45658 | G7: =INDEX(JE_Lines!$D$5:$D$1733,MATCH(A7,JE_Lines!$B$5:$B$1733,0)) -> 45655 | H7: =INDEX(JE_Lines!$I$5:$I$1733,MATCH(A7,JE_Lines!$B$5:$B$1733,0)) -> SYS_AR | I7: =INDEX(JE_Lines!$J$5:$J$1733,MATCH(A7,JE_Lines!$B$5:$B$1733,0)) -> System | J7: =IF(LEN(INDEX(JE_Lines!$K$5:$K$1733,MATCH(A7,JE_Lines!$B$5:$B$1733,0)))=0,"",INDEX(JE_Lines!$K$5:$K$1733,MATCH(A7,JE_Lines!$B$5:$B$1733,0))) -> Sales invoice batch | K7: =F7-G7 -> 3 | L7: =COUNTIFS(JE_Lines!$B$5:$B$1733,A7,JE_Lines!$F$5:$F$1733,"Revenue") -> 1 | M7: =COUNTIFS(JE_Lines!$B$5:$B$1733,A7,JE_Lines!$F$5:$F$1733,"Suspense") -> 0 | N7: =IF(ABS(E7)>Parameters!$B$23,1,0) -> 0 | O7: =IF(WEEKDAY(F7,2)>5,1,0) -> 0 | P7: =IF(K7>Parameters!$B$17,1,0) -> 0 | Q7: =IF(AND(F7<=Parameters!$B$6,F7>Parameters!$B$6-Parameters!$B$18),1,0) -> 0 | R7: =IF(COUNTIF(Parameters!$A$51:$A$58,H7)=0,1,0) -> 0 | S7: =IF(AND(I7="Manual",L7>0),1,0) -> 0 | T7: =IF(AND(C7>=Parameters!$B$22,ROUND(MOD(ROUND(C7,2),Parameters!$B$21),2)=0),1,0) -> 0 | U7: =IF(LEN(TRIM(J7))=0,1,0) -> 0 | V7: =IF(AND(I7="Manual",C7<Parameters!$B$19,C7>=Parameters!$B$19*(1-Parameters!$B$20)),1,0) -> 0 | W7: =IF(AND(I7="Manual",M7>0),1,0) -> 0 | X7: =IF(A7-A6>1,1,0) -> 0 | Y7: =N7*Parameters!$B$38+O7*Parameters!$B$39+P7*Parameters!$B$40+Q7*Parameters!$B$41+R7*Parameters!$B$42+S7*Parameters!$B$43+T7*Parameters!$B$44+U7*Parameters!$B$45+V7*Parameters!$B$46+W7*Parameters!$B$47+X7*Parameters!$B$48 -> 0 | Z7: =IF(Y7>=Parameters!$B$25,"High","")
A8: 1004 | B8: =COUNTIF(JE_Lines!$B$5:$B$1733,A8) -> 2 | C8: =SUMIFS(JE_Lines!$G$5:$G$1733,JE_Lines!$B$5:$B$1733,A8) -> 1008.74 | D8: =SUMIFS(JE_Lines!$H$5:$H$1733,JE_Lines!$B$5:$B$1733,A8) -> 1008.74 | E8: =C8-D8 -> 0 | F8: =INDEX(JE_Lines!$C$5:$C$1733,MATCH(A8,JE_Lines!$B$5:$B$1733,0)) -> 45659 | G8: =INDEX(JE_Lines!$D$5:$D$1733,MATCH(A8,JE_Lines!$B$5:$B$1733,0)) -> 45657 | H8: =INDEX(JE_Lines!$I$5:$I$1733,MATCH(A8,JE_Lines!$B$5:$B$1733,0)) -> SYS_AR | I8: =INDEX(JE_Lines!$J$5:$J$1733,MATCH(A8,JE_Lines!$B$5:$B$1733,0)) -> System | J8: =IF(LEN(INDEX(JE_Lines!$K$5:$K$1733,MATCH(A8,JE_Lines!$B$5:$B$1733,0)))=0,"",INDEX(JE_Lines!$K$5:$K$1733,MATCH(A8,JE_Lines!$B$5:$B$1733,0))) -> Sales invoice batch | K8: =F8-G8 -> 2 | L8: =COUNTIFS(JE_Lines!$B$5:$B$1733,A8,JE_Lines!$F$5:$F$1733,"Revenue") -> 1 | M8: =COUNTIFS(JE_Lines!$B$5:$B$1733,A8,JE_Lines!$F$5:$F$1733,"Suspense") -> 0 | N8: =IF(ABS(E8)>Parameters!$B$23,1,0) -> 0 | O8: =IF(WEEKDAY(F8,2)>5,1,0) -> 0 | P8: =IF(K8>Parameters!$B$17,1,0) -> 0 | Q8: =IF(AND(F8<=Parameters!$B$6,F8>Parameters!$B$6-Parameters!$B$18),1,0) -> 0 | R8: =IF(COUNTIF(Parameters!$A$51:$A$58,H8)=0,1,0) -> 0 | S8: =IF(AND(I8="Manual",L8>0),1,0) -> 0 | T8: =IF(AND(C8>=Parameters!$B$22,ROUND(MOD(ROUND(C8,2),Parameters!$B$21),2)=0),1,0) -> 0 | U8: =IF(LEN(TRIM(J8))=0,1,0) -> 0 | V8: =IF(AND(I8="Manual",C8<Parameters!$B$19,C8>=Parameters!$B$19*(1-Parameters!$B$20)),1,0) -> 0 | W8: =IF(AND(I8="Manual",M8>0),1,0) -> 0 | X8: =IF(A8-A7>1,1,0) -> 0 | Y8: =N8*Parameters!$B$38+O8*Parameters!$B$39+P8*Parameters!$B$40+Q8*Parameters!$B$41+R8*Parameters!$B$42+S8*Parameters!$B$43+T8*Parameters!$B$44+U8*Parameters!$B$45+V8*Parameters!$B$46+W8*Parameters!$B$47+X8*Parameters!$B$48 -> 0 | Z8: =IF(Y8>=Parameters!$B$25,"High","")
A9: 1005 | B9: =COUNTIF(JE_Lines!$B$5:$B$1733,A9) -> 2 | C9: =SUMIFS(JE_Lines!$G$5:$G$1733,JE_Lines!$B$5:$B$1733,A9) -> 233.11 | D9: =SUMIFS(JE_Lines!$H$5:$H$1733,JE_Lines!$B$5:$B$1733,A9) -> 233.11 | E9: =C9-D9 -> 0 | F9: =INDEX(JE_Lines!$C$5:$C$1733,MATCH(A9,JE_Lines!$B$5:$B$1733,0)) -> 45659 | G9: =INDEX(JE_Lines!$D$5:$D$1733,MATCH(A9,JE_Lines!$B$5:$B$1733,0)) -> 45656 | H9: =INDEX(JE_Lines!$I$5:$I$1733,MATCH(A9,JE_Lines!$B$5:$B$1733,0)) -> FIN02 | I9: =INDEX(JE_Lines!$J$5:$J$1733,MATCH(A9,JE_Lines!$B$5:$B$1733,0)) -> Manual | J9: =IF(LEN(INDEX(JE_Lines!$K$5:$K$1733,MATCH(A9,JE_Lines!$B$5:$B$1733,0)))=0,"",INDEX(JE_Lines!$K$5:$K$1733,MATCH(A9,JE_Lines!$B$5:$B$1733,0))) -> Accrual for sundry costs | K9: =F9-G9 -> 3 | L9: =COUNTIFS(JE_Lines!$B$5:$B$1733,A9,JE_Lines!$F$5:$F$1733,"Revenue") -> 0 | M9: =COUNTIFS(JE_Lines!$B$5:$B$1733,A9,JE_Lines!$F$5:$F$1733,"Suspense") -> 0 | N9: =IF(ABS(E9)>Parameters!$B$23,1,0) -> 0 | O9: =IF(WEEKDAY(F9,2)>5,1,0) -> 0 | P9: =IF(K9>Parameters!$B$17,1,0) -> 0 | Q9: =IF(AND(F9<=Parameters!$B$6,F9>Parameters!$B$6-Parameters!$B$18),1,0) -> 0 | R9: =IF(COUNTIF(Parameters!$A$51:$A$58,H9)=0,1,0) -> 0 | S9: =IF(AND(I9="Manual",L9>0),1,0) -> 0 | T9: =IF(AND(C9>=Parameters!$B$22,ROUND(MOD(ROUND(C9,2),Parameters!$B$21),2)=0),1,0) -> 0 | U9: =IF(LEN(TRIM(J9))=0,1,0) -> 0 | V9: =IF(AND(I9="Manual",C9<Parameters!$B$19,C9>=Parameters!$B$19*(1-Parameters!$B$20)),1,0) -> 0 | W9: =IF(AND(I9="Manual",M9>0),1,0) -> 0 | X9: =IF(A9-A8>1,1,0) -> 0 | Y9: =N9*Parameters!$B$38+O9*Parameters!$B$39+P9*Parameters!$B$40+Q9*Parameters!$B$41+R9*Parameters!$B$42+S9*Parameters!$B$43+T9*Parameters!$B$44+U9*Parameters!$B$45+V9*Parameters!$B$46+W9*Parameters!$B$47+X9*Parameters!$B$48 -> 0 | Z9: =IF(Y9>=Parameters!$B$25,"High","")
A10: 1006 | B10: =COUNTIF(JE_Lines!$B$5:$B$1733,A10) -> 2 | C10: =SUMIFS(JE_Lines!$G$5:$G$1733,JE_Lines!$B$5:$B$1733,A10) -> 37000 | D10: =SUMIFS(JE_Lines!$H$5:$H$1733,JE_Lines!$B$5:$B$1733,A10) -> 37000 | E10: =C10-D10 -> 0 | F10: =INDEX(JE_Lines!$C$5:$C$1733,MATCH(A10,JE_Lines!$B$5:$B$1733,0)) -> 45659 | G10: =INDEX(JE_Lines!$D$5:$D$1733,MATCH(A10,JE_Lines!$B$5:$B$1733,0)) -> 45659 | H10: =INDEX(JE_Lines!$I$5:$I$1733,MATCH(A10,JE_Lines!$B$5:$B$1733,0)) -> FIN01 | I10: =INDEX(JE_Lines!$J$5:$J$1733,MATCH(A10,JE_Lines!$B$5:$B$1733,0)) -> Manual | J10: =IF(LEN(INDEX(JE_Lines!$K$5:$K$1733,MATCH(A10,JE_Lines!$B$5:$B$1733,0)))=0,"",INDEX(JE_Lines!$K$5:$K$1733,MATCH(A10,JE_Lines!$B$5:$B$1733,0))) -> Round accrual 3 | K10: =F10-G10 -> 0 | L10: =COUNTIFS(JE_Lines!$B$5:$B$1733,A10,JE_Lines!$F$5:$F$1733,"Revenue") -> 0 | M10: =COUNTIFS(JE_Lines!$B$5:$B$1733,A10,JE_Lines!$F$5:$F$1733,"Suspense") -> 0 | N10: =IF(ABS(E10)>Parameters!$B$23,1,0) -> 0 | O10: =IF(WEEKDAY(F10,2)>5,1,0) -> 0 | P10: =IF(K10>Parameters!$B$17,1,0) -> 0 | Q10: =IF(AND(F10<=Parameters!$B$6,F10>Parameters!$B$6-Parameters!$B$18),1,0) -> 0 | R10: =IF(COUNTIF(Parameters!$A$51:$A$58,H10)=0,1,0) -> 0 | S10: =IF(AND(I10="Manual",L10>0),1,0) -> 0 | T10: =IF(AND(C10>=Parameters!$B$22,ROUND(MOD(ROUND(C10,2),Parameters!$B$21),2)=0),1,0) -> 1 | U10: =IF(LEN(TRIM(J10))=0,1,0) -> 0 | V10: =IF(AND(I10="Manual",C10<Parameters!$B$19,C10>=Parameters!$B$19*(1-Parameters!$B$20)),1,0) -> 0 | W10: =IF(AND(I10="Manual",M10>0),1,0) -> 0 | X10: =IF(A10-A9>1,1,0) -> 0 | Y10: =N10*Parameters!$B$38+O10*Parameters!$B$39+P10*Parameters!$B$40+Q10*Parameters!$B$41+R10*Parameters!$B$42+S10*Parameters!$B$43+T10*Parameters!$B$44+U10*Parameters!$B$45+V10*Parameters!$B$46+W10*Parameters!$B$47+X10*Parameters!$B$48 -> 2 | Z10: =IF(Y10>=Parameters!$B$25,"High","")
